{"timestamp": "2025-07-28T21:34:00.788074", "level": "error", "error_type": "Exception", "error_message": "Test error", "context": "test", "traceback": "Traceback (most recent call last):\n  File \"C:\\AutoGPT_working\\classic\\original_autogpt\\autogpt\\app\\jarvis\\core\\error_handler.py\", line 147, in wrapper\n    return func(*args, **kwargs)\n  File \"C:\\AutoGPT_working\\classic\\original_autogpt\\autogpt\\app\\tests\\unit\\test_unit_comprehensive.py\", line 74, in test_function\n    raise Exception(\"Test error\")\nException: Test error\n", "user_message": "Błąd w test: Test error", "session_id": "unknown"}
{"timestamp": "2025-07-28T21:34:00.789268", "level": "error", "error_type": "Exception", "error_message": "Test error", "context": "Test context", "traceback": "NoneType: None\n", "user_message": "Test message", "session_id": "unknown"}
{"timestamp": "2025-07-28T21:34:01.686778", "level": "error", "error_type": "ValueError", "error_message": "Test error", "context": "test_context", "traceback": "Traceback (most recent call last):\n  File \"C:\\AutoGPT_working\\classic\\original_autogpt\\autogpt\\app\\jarvis\\core\\error_handler.py\", line 147, in wrapper\n    return func(*args, **kwargs)\n  File \"C:\\AutoGPT_working\\classic\\original_autogpt\\autogpt\\app\\tests\\integration\\test_integration_comprehensive.py\", line 185, in failing_function\n    raise ValueError(\"Test error\")\nValueError: Test error\n", "user_message": "Błąd w test_context: Test error", "session_id": "unknown"}
{"timestamp": "2025-07-28T21:34:04.613859", "level": "error", "error_type": "Exception", "error_message": "Simulated error", "context": "integrity_test", "traceback": "Traceback (most recent call last):\n  File \"C:\\AutoGPT_working\\classic\\original_autogpt\\autogpt\\app\\jarvis\\core\\error_handler.py\", line 147, in wrapper\n    return func(*args, **kwargs)\n  File \"C:\\AutoGPT_working\\classic\\original_autogpt\\autogpt\\app\\tests\\regression\\test_regression_comprehensive.py\", line 301, in data_processing_function\n    raise Exception(\"Simulated error\")\nException: Simulated error\n", "user_message": "Błąd w integrity_test: Simulated error", "session_id": "unknown"}
{"timestamp": "2025-07-28T21:34:06.481265", "level": "error", "error_type": "Exception", "error_message": "Test error", "context": "performance_test", "traceback": "Traceback (most recent call last):\n  File \"C:\\AutoGPT_working\\classic\\original_autogpt\\autogpt\\app\\jarvis\\core\\error_handler.py\", line 147, in wrapper\n    return func(*args, **kwargs)\n  File \"C:\\AutoGPT_working\\classic\\original_autogpt\\autogpt\\app\\tests\\performance\\test_performance_comprehensive.py\", line 405, in failing_function\n    raise Exception(\"Test error\")\nException: Test error\n", "user_message": "Błąd w performance_test: Test error", "session_id": "unknown"}
